Workbook

Sheet Returns
A1: Date | B1: Return EURUSD | C1: Return GBPUSD | D1: Return RUBUSD | E1: Return CNYUSD | F1: Return AEDUSD | G1: Return Gold | H1: Return SILVER | I1: Return WHEAT | J1: Return WOOD | K1: Return Cotton | L1: Return Graphite | M1: Return Lithium
A2: 42005 | B2: -0.008174149 | C2: 0.0021390446 | D2: -0.031065427 | E2: 0.0023271144 | F2: 0 | G2: 0.019659714 | H2: 0.027013879 | I2: 0.010094867 | J2: -0.034830413 | K2: -0.023994717 | L2: -0.15584417 | M2: 0.0036328989
A3: 42012 | B3: -0.019641324 | C3: -0.0015147154 | D3: 0.0033091466 | E3: -0.0027880091 | F3: 0 | G3: 0.048039473 | H3: 0.07212795 | I3: -0.0025285972 | J3: -0.022791965 | K3: -0.016446274 | L3: 0.076923098 | M3: 0.0099547566
A4: 42019 | B4: -0.015550657 | C4: 0.0026882205 | D4: -0.043926107 | E4: -0.0048434829 | F4: 0 | G4: -0.0060291621 | H4: -0.0061059495 | I4: 0.0079671656 | J4: 0.022027818 | K4: 0.024650928 | L4: -0.099999991 | M4: -0.00089606679
A5: 42026 | B5: 0.0079171312 | C5: -0.0030283254 | D5: 0.044096249 | E5: -0.0016971941 | F5: 0 | G5: -0.017186387 | H5: -0.038133775 | I5: -0.0035928144 | J5: -0.018700456 | K5: 0.030114417 | L5: 0.031746002 | M5: -0.00089677189
A6: 42033 | B6: -0.011820131 | C6: 0.0079210387 | D6: -0.0035214964 | E6: 0.0022304643 | F6: 0 | G6: -0.035448684 | H6: -0.036480746 | I6: -0.012620192 | J6: 0.013565832 | K6: 0.012902187 | L6: 0.076923098 | M6: 0.023339167
A7: 42040 | B7: 0.0073104186 | C7: 0.0059877826 | D7: 0.024951099 | E7: -0.001969872 | F7: 0 | G7: -0.01583269 | H7: -0.029561112 | I7: -0.002678028 | J7: -0.034416788 | K7: 0.041921997 | L7: 0.12857148 | M7: 0.03333359
A8: 42047 | B8: -0.0057602343 | C8: 0.0068792046 | D8: 0.015780536 | E8: -0.00016016117 | F8: 2.7246984e-05 | G8: 0.001083645 | H8: 0.010707679 | I8: 0.0054924936 | J8: -0.038943854 | K8: 0.013927482 | L8: -0.037974722 | M8: 0.014431109
A9: 42054 | B9: -0.01383241 | C9: -0.005977562 | D9: 0.014390804 | E9: -0.0029694828 | F9: 0 | G9: -0.00033307611 | H9: -0.017778849 | I9: -0.0089827628 | J9: -0.0017170329 | K9: -0.029151345 | L9: -0.078947373 | M9: 0
A10: 42061 | B10: -0.042342179 | C10: -0.018520724 | D10: -0.0032233948 | E10: 0.0018714684 | F10: 0 | G10: -0.041562573 | H10: -0.048785005 | I10: 0.00036746693 | J10: -0.030959751 | K10: -0.0515642 | L10: -0.14285709 | M10: -0.035983089
A11: 42068 | B11: -0.010333058 | C11: -0.021877389 | D11: 0.010230179 | E11: 0.0020032658 | F11: -2.7246241e-05 | G11: 0.00060838904 | H11: 0.011730163 | I11: 0.012121954 | J11: -0.010649627 | K11: 0.035637289 | L11: 0 | M11: -0.011284838
A12: 42075 | B12: 0.028683213 | C12: 0.0055478199 | D12: 0.063676743 | E12: 0.0071344944 | F12: 2.7246984e-05 | G12: 0.039864533 | H12: 0.093719804 | I12: -0.002661505 | J12: 0.031933956 | K12: 0.010883488 | L12: 0 | M12: -0.0079015575
A13: 42082 | B13: -0.015033314 | C13: -0.00029653786 | D13: -0.0070849066 | E13: 0.0012606197 | F13: -5.4382323e-05 | G13: 0.0090202341 | H13: 0.0037692041 | I13: 0.0043668122 | J13: -0.050764971 | K13: -0.0091829958 | L13: 0.1333333 | M13: 0.0026547974
... A437: 45050 | B437: -0.0090293007 | C437: -0.01111107 | D437: -0.030949018 | E437: -0.0081987977 | F437: 0 | G437: -0.024526003 | H437: -0.06712225 | I437: -0.011458614 | J437: -0.014044121 | K437: 0.076523033 | L437: 0.036036001 | M437: 0.02402207
A438: 45057 | B438: -0.0088311483 | C438: -0.0053766619 | D438: 0.0041185781 | E438: -0.01130879 | F438: -5.4479122e-05 | G438: -0.00903716 | H438: -0.026818837 | I438: -0.010091368 | K438: -0.06004142 | L438: -0.069565152 | M438: -0.014265422
A439: 45064 | B439: -0.0034023707 | C439: -0.00043441275 | D439: 0.0064690004 | E439: -0.003192668 | F439: -0.00016348298 | G439: 0.00056041143 | H439: 0.015531091 | I439: 0.0017908803 | K439: 0.021536981 | L439: -0.0093458964 | M439: -0.021707521
A440: 45071 | B440: -0.0032629348 | C440: 0.0013423185 | D440: -0.020967822 | E440: -0.0055907822 | F440: 0 | G440: -0.010794884 | H440: -0.001491086 | I440: -0.0096259626 | K440: 0.018327728 | L440: -0.042452792 | M440: 0.037639676
A441: 45078 | B441: 0.0085343797 | C441: 0.014346604 | D441: -0.030983694 | E441: -0.006656007 | F441: 0 | G441: 0.0064858691 | H441: 0.025811744 | I441: -0.0029158567 | K441: -0.03787791 | L441: -0.029556622 | M441: 0.028987766
A442: 45085 | B442: 0.012143397 | C442: 0.012573819 | D442: -0.0094316877 | E442: -0.0019914271 | F442: 0 | G442: -0.01125147 | H442: -0.052819848 | I442: 0.0023673583 | K442: -0.030321596 | L442: 0.0020304307 | M442: -0.0058497599
A443: 45092 | B443: 0.0033748627 | C443: -0.0016185485 | D443: -0.0073353607 | E443: -0.0052502423 | F443: -5.4490998e-05 | G443: -0.010862256 | H443: 0.0041275078 | I443: 0.006946374 | K443: 0.010213154 | L443: -0.1306991 | M443: -0.015949194
A444: 45099 | B444: -0.0065962508 | C444: -0.0021239305 | D444: -0.051408886 | E444: 0.00072085942 | F444: 0 | G444: 0.0038173543 | H444: 0.014386937 | I444: -0.01669426 | K444: 0.029081305 | L444: 0.13519813 | M444: 0.049881992
A445: 45106 | B445: 0.011862067 | C445: 0.017074008 | D445: -0.0055270556 | E445: 0.00059648436 | F445: 5.4493968e-05 | G445: 0.01906646 | H445: 0.039746474 | I445: 0.0081380665 | K445: 0.00072777672 | L445: 0.057494862 | M445: 0.023433489
A446: 45113 | B446: 0.019504686 | C446: 0.0077557916 | D446: -0.0054966067 | E446: 0.004164755 | F446: -2.7245499e-05 | G446: 0.010888482 | H446: 0.045607214 | I446: 0.0065414057 | K446: 0.037692407 | L446: 0.04854376 | M446: -0.010872653
A447: 45120 | B447: -0.015890587 | C447: -0.010830915 | D447: 0.0088725753 | E447: 0.006152445 | F447: 2.7246241e-05 | G447: -0.0043489131 | H447: -0.015623106 | I447: -0.0076050885 | K447: 0.050922687 | L447: 0.04629625 | M447: -0.016785392
A448: 45127 | B448: -0.003852836 | C448: -0.0076133989 | D448: -0.023924243 | E448: -0.0057270149 | F448: -2.7245499e-05 | G448: -0.015998781 | H448: -0.043142035 | I448: -0.011982723 | K448: -0.054456561 | L448: -0.11504424 | M448: -0.039432013
A449: 45134 | B449: -0.0044492792 | C449: -0.0042301706 | D449: -0.049346479 | E449: -0.0054326823 | F449: 0 | G449: -0.011355425 | H449: -0.046476387 | I449: 0.0053589057 | K449: 0.012106238 | L449: -0.06099999 | M449: -0.024221453
... A522: 45645 | B522: 0.0003434439 | C522: 0.0010415563 | D522: -0.095432682 | E522: -0.00047961998 | F522: 0.00021243361 | G522: 0.0035114317 | H522: -0.034496576 | I522: 0.0017271157 | K522: -0.005524822 | L522: 0.03275106 | M522: -0.045858782
A523: 45652

Sheet Rolling Correlation
A1: Date | B1: Return EURUSD_vs_Return GBPUSD | C1: Return EURUSD_vs_Return RUBUSD | D1: Return EURUSD_vs_Return CNYUSD | E1: Return EURUSD_vs_Return AEDUSD | F1: Return EURUSD_vs_Return Gold | G1: Return EURUSD_vs_Return Silver | H1: Return EURUSD_vs_Return Wheat | I1: Return EURUSD_vs_Return Wood | J1: Return EURUSD_vs_Return Cotton | K1: Return EURUSD_vs_Return Graphite | L1: Return EURUSD_vs_Return Lithium | M1: Return GBPUSD_vs_Return RUBUSD | N1: Return GBPUSD_vs_Return CNYUSD | O1: Return GBPUSD_vs_Return AEDUSD | P1: Return GBPUSD_vs_Return Gold | Q1: Return GBPUSD_vs_Return Silver | R1: Return GBPUSD_vs_Return Wheat | S1: Return GBPUSD_vs_Return Wood | T1: Return GBPUSD_vs_Return Cotton | U1: Return GBPUSD_vs_Return Graphite | V1: Return GBPUSD_vs_Return Lithium | W1: Return RUBUSD_vs_Return CNYUSD | X1: Return RUBUSD_vs_Return AEDUSD | Y1: Return RUBUSD_vs_Return Gold | Z1: Return RUBUSD_vs_Return Silver | AA1: Return RUBUSD_vs_Return Wheat | AB1: Return RUBUSD_vs_Return Wood | AC1: Return RUBUSD_vs_Return Cotton | AD1: Return RUBUSD_vs_Return Graphite | AE1: Return RUBUSD_vs_Return Lithium | AF1: Return CNYUSD_vs_Return AEDUSD | AG1: Return CNYUSD_vs_Return Gold | AH1: Return CNYUSD_vs_Return Silver | AI1: Return CNYUSD_vs_Return Wheat | AJ1: Return CNYUSD_vs_Return Wood | AK1: Return CNYUSD_vs_Return Cotton | AL1: Return CNYUSD_vs_Return Graphite | AM1: Return CNYUSD_vs_Return Lithium | AN1: Return AEDUSD_vs_Return Gold | AO1: Return AEDUSD_vs_Return Silver | AP1: Return AEDUSD_vs_Return Wheat | AQ1: Return AEDUSD_vs_Return Wood | AR1: Return AEDUSD_vs_Return Cotton | AS1: Return AEDUSD_vs_Return Graphite | AT1: Return AEDUSD_vs_Return Lithium | AU1: Return Gold_vs_Return Silver | AV1: Return Gold_vs_Return Wheat | AW1: Return Gold_vs_Return Wood | AX1: Return Gold_vs_Return Cotton | AY1: Return Gold_vs_Return Graphite | AZ1: Return Gold_vs_Return Lithium | BA1: Return Silver_vs_Return Wheat | BB1: Return Silver_vs_Return Wood | BC1: Return Silver_vs_Return Cotton | BD1: Return Silver_vs_Return Graphite | BE1: Return Silver_vs_Return Lithium | BF1: Return Wheat_vs_Return Wood | BG1: Return Wheat_vs_Return Cotton | BH1: Return Wheat_vs_Return Graphite | BI1: Return Wheat_vs_Return Lithium | BJ1: Return Wood_vs_Return Cotton | BK1: Return Wood_vs_Return Graphite | BL1: Return Wood_vs_Return Lithium | BM1: Return Cotton_vs_Return Graphite | BN1: Return Cotton_vs_Return Lithium | BO1: Return Graphite_vs_Return Lithium
A2: 42005 | B2: =CORREL(Returns!$B2:$B53,Returns!C2:C53) -> 0.34701575 | C2: =CORREL(Returns!$B2:$B53,Returns!D2:D53) -> -0.12743178 | D2: =CORREL(Returns!$B2:$B53,Returns!E2:E53) -> -0.078661729 | E2: =CORREL(Returns!$B2:$B53,Returns!F2:F53) -> -0.12515853 | F2: =CORREL(Returns!$B2:$B53,Returns!G2:G53) -> 0.24234072 | G2: =CORREL(Returns!$B2:$B53,Returns!H2:H53) -> 0.065036254 | H2: =CORREL(Returns!$B2:$B53,Returns!I2:I53) -> -0.1957935 | I2: =CORREL(Returns!$B2:$B53,Returns!J2:J53) -> 0.15870586 | ... L2: =CORREL(Returns!$B2:$B53,Returns!M2:M53) -> -0.076790199 | M2: =CORREL(Returns!$C2:$C53,Returns!D2:D53) -> -0.1242084 | N2: =CORREL(Returns!$C2:$C53,Returns!E2:E53) -> -0.075143037 | O2: =CORREL(Returns!$C2:$C53,Returns!F2:F53) -> 0.29019677 | P2: =CORREL(Returns!$C2:$C53,Returns!G2:G53) -> 0.13600202 | Q2: =CORREL(Returns!$C2:$C53,Returns!H2:H53) -> 0.15153498 | R2: =CORREL(Returns!$C2:$C53,Returns!I2:I53) -> -0.12562414 | S2: =CORREL(Returns!$C2:$C53,Returns!J2:J53) -> -0.12343794 | T2: =CORREL(Returns!$C2:$C53,Returns!K2:K53) -> 0.14038452 | ... V2: =CORREL(Returns!$C2:$C53,Returns!M2:M53) -> 0.33563488 | W2: =CORREL(Returns!$D2:$D53,Returns!E2:E53) -> -0.17866101 | X2: =CORREL(Returns!$D2:$D53,Returns!F2:F53) -> -0.075293369 | Y2: =CORREL(Returns!$D2:$D53,Returns!G2:G53) -> 0.21353516 | Z2: =CORREL(Returns!$D2:$D53,Returns!H2:H53) -> 0.0503293 | AA2: =CORREL(Returns!$D2:$D53,Returns!I2:I53) -> 0.21040378 | AB2: =CORREL(Returns!$D2:$D53,Returns!J2:J53) -> -0.0055113017 | AC2: =CORREL(Returns!$D2:$D53,Returns!K2:K53) -> -0.15078154 | AD2: =CORREL(Returns!$D2:$D53,Returns!L2:L53) -> -0.023774595 | AE2: =CORREL(Returns!$D2:$D53,Returns!M2:M53) -> -0.24427602 | AF2: =CORREL(Returns!$E2:$E53,Returns!F2:F53) -> 0.038114902 | AG2: =CORREL(Returns!$E2:$E53,Returns!G2:G53) -> -0.1896991 | AH2: =CORREL(Returns!$E2:$E53,Returns!H2:H53) -> 0.0064442729 | AI2: =CORREL(Returns!$E2:$E53,Returns!I2:I53) -> -0.17104266 | AJ2: =CORREL(Returns!$E2:$E53,Returns!J2:J53) -> 0.033479739 | AK2: =CORREL(Returns!$E2:$E53,Returns!K2:K53) -> 0.023775096 | AL2: =CORREL(Returns!$E2:$E53,Returns!L2:L53) -> -0.063102712 | AM2: =CORREL(Returns!$E2:$E53,Returns!M2:M53) -> 0.22563581 | AN2: =CORREL(Returns!$F2:$F53,Returns!G2:G53) -> -0.054495896 | AO2: =CORREL(Returns!$F2:$F53,Returns!H2:H53) -> 0.17869944 | AP2: =CORREL(Returns!$F2:$F53,Returns!I2:I53) -> -0.031897021 | AQ2: =CORREL(Returns!$F2:$F53,Returns!J2:J53) -> -0.11471298 | AR2: =CORREL(Returns!$F2:$F53,Returns!K2:K53) -> 0.20733115 | AS2: =CORREL(Returns!$F2:$F53,Returns!L2:L53) -> 0.0066715362 | AT2: =CORREL(Returns!$F2:$F53,Returns!M2:M53) -> 0.39765075 | AU2: =CORREL(Returns!$G2:$G53,Returns!H2:H53) -> 0.78128005 | AV2: =CORREL(Returns!$G2:$G53,Returns!I2:I53) -> 0.25140909 | AW2: =CORREL(Returns!$G2:$G53,Returns!J2:J53) -> 0.19435297 | AX2: =CORREL(Returns!$G2:$G53,Returns!K2:K53) -> 0.10046213 | AY2: =CORREL(Returns!$G2:$G53,Returns!L2:L53) -> 0.12356395 | AZ2: =CORREL(Returns!$G2:$G53,Returns!M2:M53) -> 0.031777666 | BA2: =CORREL(Returns!$H2:$H53,Returns!I2:I53) -> 0.1706382 | BB2: =CORREL(Returns!$H2:$H53,Returns!J2:J53) -> 0.10299685 | BC2: =CORREL(Returns!$H2:$H53,Returns!K2:K53) -> 0.21752151 | BD2: =CORREL(Returns!$H2:$H53,Returns!L2:L53) -> 0.1388372 | BE2: =CORREL(Returns!$H2:$H53,Returns!M2:M53) -> 0.33636862 | BF2: =CORREL(Returns!$I2:$I53,Returns!J2:J53) -> -0.11343699 | BG2: =CORREL(Returns!$I2:$I53,Returns!K2:K53) -> -0.10490411 | BH2: =CORREL(Returns!$I2:$I53,Returns!L2:L53) -> -0.20873263 | BI2: =CORREL(Returns!$I2:$I53,Returns!M2:M53) -> -0.33494034 | BJ2: =CORREL(Returns!$J2:$J53,Returns!K2:K53) -> 0.29041092 | BK2: =CORREL(Returns!$J2:$J53,Returns!L2:L53) -> 0.023880297 | BL2: =CORREL(Returns!$J2:$J53,Returns!M2:M53) -> 0.1006777 | BM2: =CORREL(Returns!$K2:$K53,Returns!L2:L53) -> 0.076698562 | BN2: =CORREL(Returns!$K2:$K53,Returns!M2:M53) -> 0.38859948 | BO2: =CORREL(Returns!$L2:$L53,Returns!M2:M53) -> 0.2398949
A3: 42012 | B3: =CORREL(Returns!B3:B54,Returns!C3:C54) -> 0.32399477 | C3: =CORREL(Returns!$B3:$B54,Returns!D3:D54) -> -0.13085546 | D3: =CORREL(Returns!$B3:$B54,Returns!E3:E54) -> -0.091045592 | E3: =CORREL(Returns!$B3:$B54,Returns!F3:F54) -> -0.11790185 | F3: =CORREL(Returns!$B3:$B54,Returns!G3:G54) -> 0.25145123 | G3: =CORREL(Returns!$B3:$B54,Returns!H3:H54) -> 0.07727719 | H3: =CORREL(Returns!$B3:$B54,Returns!I3:I54) -> -0.16576461 | I3: =CORREL(Returns!$B3:$B54,Returns!J3:J54) -> 0.15401399 | J3: =CORREL(Returns!$B3:$B54,Returns!K3:K54) -> 0.26302423 | ... L3: =CORREL(Returns!$B3:$B54,Returns!M3:M54) -> -0.096088624 | M3: =CORREL(Returns!$C3:$C54,Returns!D3:D54) -> -0.11529474 | N3: =CORREL(Returns!$C3:$C54,Returns!E3:E54) -> -0.029887251 | O3: =CORREL(Returns!$C3:$C54,Returns!F3:F54) -> 0.26918382 | P3: =CORREL(Returns!$C3:$C54,Returns!G3:G54) -> 0.13219572 | Q3: =CORREL(Returns!$C3:$C54,Returns!H3:H54) -> 0.13291065 | R3: =CORREL(Returns!$C3:$C54,Returns!I3:I54) -> -0.17075997 | S3: =CORREL(Returns!$C3:$C54,Returns!J3:J54) -> -0.11901826 | T3: =CORREL(Returns!$C3:$C54,Returns!K3:K54) -> 0.14204357 | ... V3: =CORREL(Returns!$C3:$C54,Returns!M3:M54) -> 0.36910249 | W3: =CORREL(Returns!$D3:$D54,Returns!E3:E54) -> -0.16562237 | X3: =CORREL(Returns!$D3:$D54,Returns!F3:F54) -> -0.077262379 | Y3: =CORREL(Returns!$D3:$D54,Returns!G3:G54) -> 0.21897072 | Z3: =CORREL(Returns!$D3:$D54,Returns!H3:H54) -> 0.050962369 | AA3: =CORREL(Returns!$D3:$D54,Returns!I3:I54) -> 0.20920627 | AB3: =CORREL(Returns!$D3:$D54,Returns!J3:J54) -> -0.007486947 | AC3: =CORREL(Returns!$D3:$D54,Returns!K3:K54) -> -0.15432183 | AD3: =CORREL(Returns!$D3:$D54,Returns!L3:L54) -> -0.020707604 | AE3: =CORREL(Returns!$D3:$D54,Returns!M3:M54) -> -0.22717241 | AF3: =CORREL(Returns!$E3:$E92,Returns!F3:F92) -> -0.0050327495 | AG3: =CORREL(Returns!$E3:$E92,Returns!G3:G92) -> -0.050426675 | AH3: =CORREL(Returns!$E3:$E92,Returns!H3:H92) -> 0.027235169 | AI3: =CORREL(Returns!$E3:$E92,Returns!I3:I92) -> -0.21316314 | AJ3: =CORREL(Returns!$E3:$E92,Returns!J3:J92) -> -0.007301809 | AK3: =CORREL(Returns!$E3:$E92,Returns!K3:K92) -> 0.070971851 | AL3: =CORREL(Returns!$E3:$E92,Returns!L3:L92) -> 0.13568675 | AM3: =CORREL(Returns!$E3:$E92,Returns!M3:M92) -> 0.21800663 | AN3: =CORREL(Returns!$F3:$F54,Returns!G3:G54) -> -0.055825355 | AO3: =CORREL(Returns!$F3:$F54,Returns!H3:H54) -> 0.1837068 | AP3: =CORREL(Returns!$F3:$F54,Returns!I3:I54) -> -0.016890623 | AQ3: =CORREL(Returns!$F3:$F54,Returns!J3:J54) -> -0.11465197 | AR3: =CORREL(Returns!$F3:$F54,Returns!K3:K54) -> 0.20852791 | AS3: =CORREL(Returns!$F3:$F54,Returns!L3:L54) -> -0.012428837 | AT3: =CORREL(Returns!$F3:$F54,Returns!M3:M54) -> 0.36265067 | AU3: =CORREL(Returns!$G3:$G54,Returns!H3:H54) -> 0.77561487 | AV3: =CORREL(Returns!$G3:$G54,Returns!I3:I54) -> 0.221084 | AW3: =CORREL(Returns!$G3:$G54,Returns!J3:J54) -> 0.21077219 | AX3: =CORREL(Returns!$G3:$G54,Returns!K3:K54) -> 0.11960081 | AY3: =CORREL(Returns!$G3:$G54,Returns!L3:L54) -> 0.16111322 | AZ3: =CORREL(Returns!$G3:$G54,Returns!M3:M54) -> 0.030563736 | BA3: =CORREL(Returns!$H3:$H54,Returns!I3:I54) -> 0.16007612 | BB3: =CORREL(Returns!$H3:$H54,Returns!J3:J54) -> 0.11480107 | BC3: =CORREL(Returns!$H3:$H54,Returns!K3:K54) -> 0.23402406 | BD3: =CORREL(Returns!$H3:$H54,Returns!L3:L54) -> 0.14914709 | BE3: =CORREL(Returns!$H3:$H54,Returns!M3:M54) -> 0.30621619 | BF3: =CORREL(Returns!$I3:$I54,Returns!J3:J54) -> -0.093589367 | BG3: =CORREL(Returns!$I3:$I54,Returns!K3:K54) -> -0.079489968 | BH3: =CORREL(Returns!$I3:$I54,Returns!L3:L54) -> -0.20989149 | BI3: =CORREL(Returns!$I3:$I54,Returns!M3:M54) -> -0.38281784 | BJ3: =CORREL(Returns!$J3:$J54,Returns!K3:K54) -> 0.28258819 | BK3: =CORREL(Returns!$J3:$J54,Returns!L3:L54) -> 0.0013042655 | BL3: =CORREL(Returns!$J3:$J54,Returns!M3:M54) -> 0.099006233 | BM3: =CORREL(Returns!$K3:$K54,Returns!L3:L54) -> 0.047929386 | BN3: =CORREL(Returns!$K3:$K54,Returns!M3:M54) -> 0.37938665 | BO3: =CORREL(Returns!$L3:$L54,Returns!M3:M54) -> 0.30391394
A4: 42019 | B4: =CORREL(Returns!B4:B55,Returns!C4:C55) -> 0.30563794 | C4: =CORREL(Returns!$B4:$B55,Returns!D4:D55) -> -0.13675646 | D4: =CORREL(Returns!$B4:$B55,Returns!E4:E55) -> -0.10167892 | E4: =CORREL(Returns!$B4:$B55,Returns!F4:F55) -> -0.11434533 | F4: =CORREL(Returns!$B4:$B55,Returns!G4:G55) -> 0.3357934 | G4: =CORREL(Returns!$B4:$B55,Returns!H4:H55) -> 0.13220123 | H4: =CORREL(Returns!$B4:$B55,Returns!I4:I55) -> -0.16537172 | I4: =CORREL(Returns!$B4:$B55,Returns!J4:J55) -> 0.13202454 | J4: =CORREL(Returns!$B4:$B55,Returns!K4:K55) -> 0.25139942 | ... L4: =CORREL(Returns!$B4:$B55,Returns!M4:M55) -> -0.093673022 | M4: =CORREL(Returns!$C4:$C55,Returns!D4:D55) -> -0.10889096 | N4: =CORREL(Returns!$C4:$C55,Returns!E4:E55) -> -0.030954566 | O4: =CORREL(Returns!$C4:$C55,Returns!F4:F55) -> 0.24760991 | P4: =CORREL(Returns!$C4:$C55,Returns!G4:G55) -> 0.10812842 | Q4: =CORREL(Returns!$C4:$C55,Returns!H4:H55) -> 0.1345827 | R4: =CORREL(Returns!$C4:$C55,Returns!I4:I55) -> -0.19345436 | S4: =CORREL(Returns!$C4:$C55,Returns!J4:J55) -> -0.077800974 | T4: =CORREL(Returns!$C4:$C55,Returns!K4:K55) -> 0.14320141 | ... V4: =CORREL(Returns!$C4:$C55,Returns!M4:M55) -> 0.38061452 | W4: =CORREL(Returns!$D4:$D55,Returns!E4:E55) -> -0.16719944 | X4: =CORREL(Returns!$D4:$D55,Returns!F4:F55) -> -0.078516215 | Y4: =CORREL(Returns!$D4:$D55,Returns!G4:G55) -> 0.234382 | Z4: =CORREL(Returns!$D4:$D55,Returns!H4:H55) -> 0.058757851 | AA4: =CORREL(Returns!$D4:$D55,Returns!I4:I55) -> 0.20410371 | AB4: =CORREL(Returns!$D4:$D55,Returns!J4:J55) -> -0.0049515569 | AC4: =CORREL(Returns!$D4:$D55,Returns!K4:K55) -> -0.15610699 | AD4: =CORREL(Returns!$D4:$D55,Returns!L4:L55) -> -0.016970331 | AE4: =CORREL(Returns!$D4:$D55,Returns!M4:M55) -> -0.22344019 | AF4: =CORREL(Returns!$E4:$E93,Returns!F4:F93) -> -0.054719356 | AG4: =CORREL(Returns!$E4:$E93,Returns!G4:G93) -> -0.026998807 | AH4: =CORREL(Returns!$E4:$E93,Returns!H4:H93) -> 0.044018013 | AI4: =CORREL(Returns!$E4:$E93,Returns!I4:I93) -> -0.20203665 | AJ4: =CORREL(Returns!$E4:$E93,Returns!J4:J93) -> -0.013705295 | AK4: =CORREL(Returns!$E4:$E93,Returns!K4:K93) -> 0.059947429 | AL4: =CORREL(Returns!$E4:$E93,Returns!L4:L93) -> 0.13764583 | AM4: =CORREL(Returns!$E4:$E93,Returns!M4:M93) -> 0.23561603 | AN4: =CORREL(Returns!$F4:$F55,Returns!G4:G55) -> -0.047226416 | AO4: =CORREL(Returns!$F4:$F55,Returns!H4:H55) -> 0.19313733 | AP4: =CORREL(Returns!$F4:$F55,Returns!I4:I55) -> -0.0071854038 | AQ4: =CORREL(Returns!$F4:$F55,Returns!J4:J55) -> -0.1259044 | AR4: =CORREL(Returns!$F4:$F55,Returns!K4:K55) -> 0.20701902 | AS4: =CORREL(Returns!$F4:$F55,Returns!L4:L55) -> -0.01817394 | AT4: =CORREL(Returns!$F4:$F55,Returns!M4:M55) -> 0.3536119 | AU4: =CORREL(Returns!$G4:$G55,Returns!H4:H55) -> 0.74634626 | AV4: =CORREL(Returns!$G4:$G55,Returns!I4:I55) -> 0.26740547 | AW4: =CORREL(Returns!$G4:$G55,Returns!J4:J55) -> 0.21251273 | AX4: =CORREL(Returns!$G4:$G55,Returns!K4:K55) -> 0.15401962 | AY4: =CORREL(Returns!$G4:$G55,Returns!L4:L55) -> 0.11702371 | AZ4: =CORREL(Returns!$G4:$G55,Returns!M4:M55) -> -0.0034758981 | BA4: =CORREL(Returns!$H4:$H55,Returns!I4:I55) -> 0.18261546 | BB4: =CORREL(Returns!$H4:$H55,Returns!J4:J55) -> 0.13264045 | BC4: =CORREL(Returns!$H4:$H55,Returns!K4:K55) -> 0.27106871 | BD4: =CORREL(Returns!$H4:$H55,Returns!L4:L55) -> 0.12032989 | BE4: =CORREL(Returns!$H4:$H55,Returns!M4:M55) -> 0.29944609 | BF4: =CORREL(Returns!$I4:$I55,Returns!J4:J55) -> -0.11811302 | BG4: =CORREL(Returns!$I4:$I55,Returns!K4:K55) -> -0.086053937 | BH4: =CORREL(Returns!$I4:$I55,Returns!L4:L55) -> -0.21426737 | BI4: =CORREL(Returns!$I4:$I55,Returns!M4:M55) -> -0.38880848 | BJ4: =CORREL(Returns!$J4:$J55,Returns!K4:K55) -> 0.27822315 | BK4: =CORREL(Returns!$J4:$J55,Returns!L4:L55) -> 0.022608183 | BL4: =CORREL(Returns!$J4:$J55,Returns!M4:M55) -> 0.11825178 | BM4: =CORREL(Returns!$K4:$K55,Returns!L4:L55) -> 0.059816971 | BN4: =CORREL(Returns!$K4:$K55,Returns!M4:M55) -> 0.38670028 | BO4: =CORREL(Returns!$L4:$L55,Returns!M4:M55) -> 0.30516068
A5: 42026 | B5: =CORREL(Returns!B5:B56,Returns!C5:C56) -> 0.30610619 | C5: =CORREL(Returns!$B5:$B56,Returns!D5:D56) -> -0.13984883 | D5: =CORREL(Returns!$B5:$B56,Returns!E5:E56) -> -0.12207132 | E5: =CORREL(Returns!$B5:$B56,Returns!F5:F56) -> -0.11424557 | F5: =CORREL(Returns!$B5:$B56,Returns!G5:G56) -> 0.33209267 | G5: =CORREL(Returns!$B5:$B56,Returns!H5:H56) -> 0.12839211 | H5: =CORREL(Returns!$B5:$B56,Returns!I5:I56) -> -0.14698156 | I5: =CORREL(Returns!$B5:$B56,Returns!J5:J56) -> 0.14115292 | J5: =CORREL(Returns!$B5:$B56,Returns!K5:K56) -> 0.27160002 | ... L5: =CORREL(Returns!$B5:$B56,Returns!M5:M56) -> -0.094069396 | M5: =CORREL(Returns!$C5:$C56,Returns!D5:D56) -> -0.10973956 | N5: =CORREL(Returns!$C5:$C56,Returns!E5:E56) -> -0.021906143 | O5: =CORREL(Returns!$C5:$C56,Returns!F5:F56) -> 0.2386976 | P5: =CORREL(Returns!$C5:$C56,Returns!G5:G56) -> 0.11951961 | Q5: =CORREL(Returns!$C5:$C56,Returns!H5:H56) -> 0.14802101 | R5: =CORREL(Returns!$C5:$C56,Returns!I5:I56) -> -0.20187515 | S5: =CORREL(Returns!$C5:$C56,Returns!J5:J56) -> -0.070717321 | T5: =CORREL(Returns!$C5:$C56,Returns!K5:K56) -> 0.12253048 | ... V5: =CORREL(Returns!$C5:$C56,Returns!M5:M56) -> 0.38274866 | W5: =CORREL(Returns!$D5:$D56,Returns!E5:E56) -> -0.17176452 | X5: =CORREL(Returns!$D5:$D56,Returns!F5:F56) -> -0.077737692 | Y5: =CORREL(Returns!$D5:$D56,Returns!G5:G56) -> 0.23184594 | Z5: =CORREL(Returns!$D5:$D56,Returns!H5:H56) -> 0.056426498 | AA5: =CORREL(Returns!$D5:$D56,Returns!I5:I56) -> 0.21024032 | AB5: =CORREL(Returns!$D5:$D56,Returns!J5:J56) -> -0.0046945776 | AC5: =CORREL(Returns!$D5:$D56,Returns!K5:K56) -> -0.15246904 | AD5: =CORREL(Returns!$D5:$D56,Returns!L5:L56) -> -0.020647742 | AE5: =CORREL(Returns!$D5:$D56,Returns!M5:M56) -> -0.22385369 | AF5: =CORREL(Returns!$E5:$E94,Returns!F5:F94) -> -0.054968595 | AG5: =CORREL(Returns!$E5:$E94,Returns!G5:G94) -> -0.03421956 | AH5: =CORREL(Returns!$E5:$E94,Returns!H5:H94) -> 0.040794701 | AI5: =CORREL(Returns!$E5:$E94,Returns!I5:I94) -> -0.1933969 | AJ5: =CORREL(Returns!$E5:$E94,Returns!J5:J94) -> -0.00011298097 | AK5: =CORREL(Returns!$E5:$E94,Returns!K5:K94) -> 0.062724574 | AL5: =CORREL(Returns!$E5:$E94,Returns!L5:L94) -> 0.13177387 | AM5: =CORREL(Returns!$E5:$E94,Returns!M5:M94) -> 0.23219662 | AN5: =CORREL(Returns!$F5:$F56,Returns!G5:G56) -> -0.05017017 | AO5: =CORREL(Returns!$F5:$F56,Returns!H5:H56) -> 0.18810456 | AP5: =CORREL(Returns!$F5:$F56,Returns!I5:I56) -> -0.006870487 | AQ5: =CORREL(Returns!$F5:$F56,Returns!J5:J56) -> -0.12828115 | AR5: =CORREL(Returns!$F5:$F56,Returns!K5:K56) -> 0.2112314 | AS5: =CORREL(Returns!$F5:$F56,Returns!L5:L56) -> -0.019975213 | AT5: =CORREL(Returns!$F5:$F56,Returns!M5:M56) -> 0.35111519 | AU5: =CORREL(Returns!$G5:$G56,Returns!H5:H56) -> 0.7480934 | AV5: =CORREL(Returns!$G5:$G56,Returns!I5:I56) -> 0.27443598 | AW5: =CORREL(Returns!$G5:$G56,Returns!J5:J56) -> 0.21881252 | AX5: =CORREL(Returns!$G5:$G56,Returns!K5:K56) -> 0.14959435 | AY5: =CORREL(Returns!$G5:$G56,Returns!L5:L56) -> 0.11680557 | AZ5: =CORREL(Returns!$G5:$G56,Returns!M5:M56) -> 0.00044588735 | BA5: =CORREL(Returns!$H5:$H56,Returns!I5:I56) -> 0.18574037 | BB5: =CORREL(Returns!$H5:$H56,Returns!J5:J56) -> 0.13906048 | BC5: =CORREL(Returns!$H5:$H56,Returns!K5:K56) -> 0.26224581 | BD5: =CORREL(Returns!$H5:$H56,Returns!L5:L56) -> 0.12281285 | BE5: =CORREL(Returns!$H5:$H56,Returns!M5:M56) -> 0.30245261 | BF5: =CORREL(Returns!$I5:$I56,Returns!J5:J56) -> -0.13254477 | BG5: =CORREL(Returns!$I5:$I56,Returns!K5:K56) -> -0.10620963 | BH5: =CORREL(Returns!$I5:$I56,Returns!L5:L56) -> -0.19474785 | BI5: =CORREL(Returns!$I5:$I56,Returns!M5:M56) -> -0.39606223 | BJ5: =CORREL(Returns!$J5:$J56,Returns!K5:K56) -> 0.26464683 | BK5: =CORREL(Returns!$J5:$J56,Returns!L5:L56) -> 0.036065172 | BL5: =CORREL(Returns!$J5:$J56,Returns!M5:M56) -> 0.12023568 | BM5: =CORREL(Returns!$K5:$K56,Returns!L5:L56) -> 0.074186948 | BN5: =CORREL(Returns!$K5:$K56,Returns!M5:M56) -> 0.3812565 | BO5: =CORREL(Returns!$L5:$L56,Returns!M5:M56) -> 0.3114645
A6: 42033 | B6: =CORREL(Returns!B6:B57,Returns!C6:C57) -> 0.31167288 | C6: =CORREL(Returns!$B6:$B57,Returns!D6:D57) -> -0.13965374 | D6: =CORREL(Returns!$B6:$B57,Returns!E6:E57) -> -0.11740852 | E6: =CORREL(Returns!$B6:$B57,Returns!F6:F57) -> -0.11809854 | F6: =CORREL(Returns!$B6:$B57,Returns!G6:G57) -> 0.34702378 | G6: =CORREL(Returns!$B6:$B57,Returns!H6:H57) -> 0.14514541 | H6: =CORREL(Returns!$B6:$B57,Returns!I6:I57) -> -0.12949918 | I6: =CORREL(Returns!$B6:$B57,Returns!J6:J57) -> 0.15046358 | J6: =CORREL(Returns!$B6:$B57,Returns!K6:K57) -> 0.26722722 | ... L6: =CORREL(Returns!$B6:$B57,Returns!M6:M57) -> -0.089778458 | M6: =CORREL(Returns!$C6:$C57,Returns!D6:D57) -> -0.11132598 | N6: =CORREL(Returns!$C6:$C57,Returns!E6:E57) -> -0.019022649 | O6: =CORREL(Returns!$C6:$C57,Returns!F6:F57) -> 0.23224762 | P6: =CORREL(Returns!$C6:$C57,Returns!G6:G57) -> 0.12735617 | Q6: =CORREL(Returns!$C6:$C57,Returns!H6:H57) -> 0.1512058 | R6: =CORREL(Returns!$C6:$C57,Returns!I6:I57) -> -0.18761382 | S6: =CORREL(Returns!$C6:$C57,Returns!J6:J57) -> -0.063008472 | T6: =CORREL(Returns!$C6:$C57,Returns!K6:K57) -> 0.1323254 | ... V6: =CORREL(Returns!$C6:$C57,Returns!M6:M57) -> 0.38703122 | W6: =CORREL(Returns!$D6:$D57,Returns!E6:E57) -> -0.17306225 | X6: =CORREL(Returns!$D6:$D57,Returns!F6:F57) -> -0.076063167 | Y6: =CORREL(Returns!$D6:$D57,Returns!G6:G57) -> 0.22433389 | Z6: =CORREL(Returns!$D6:$D57,Returns!H6:H57) -> 0.052370204 | AA6: =CORREL(Returns!$D6:$D57,Returns!I6:I57) -> 0.20223932 | AB6: =CORREL(Returns!$D6:$D57,Returns!J6:J57) -> -0.0078282223 | AC6: =CORREL(Returns!$D6:$D57,Returns!K6:K57) -> -0.15241235 | AD6: =CORREL(Returns!$D6:$D57,Returns!L6:L57) -> -0.026175661 | AE6: =CORREL(Returns!$D6:$D57,Returns!M6:M57) -> -0.22447198 | AF6: =CORREL(Returns!$E6:$E95,Returns!F6:F95) -> -0.054518595 | AG6: =CORREL(Returns!$E6:$E95,Returns!G6:G95) -> -0.034389629 | AH6: =CORREL(Returns!$E6:$E95,Returns!H6:H95) -> 0.03912844 | AI6: =CORREL(Returns!$E6:$E95,Returns!I6:I95) -> -0.18819947 | AJ6: =CORREL(Returns!$E6:$E95,Returns!J6:J95) -> 0.0068309453 | AK6: =CORREL(Returns!$E6:$E95,Returns!K6:K95) -> 0.075278986 | AL6: =CORREL(Returns!$E6:$E95,Returns!L6:L95) -> 0.13193275 | AM6: =CORREL(Returns!$E6:$E95,Returns!M6:M95) -> 0.23615681 | AN6: =CORREL(Returns!$F6:$F57,Returns!G6:G57) -> -0.062846278 | AO6: =CORREL(Returns!$F6:$F57,Returns!H6:H57) -> 0.18156221 | AP6: =CORREL(Returns!$F6:$F57,Returns!I6:I57) -> -0.020912872 | AQ6: =CORREL(Returns!$F6:$F57,Returns!J6:J57) -> -0.13630931 | AR6: =CORREL(Returns!$F6:$F57,Returns!K6:K57) -> 0.20599231 | AS6: =CORREL(Returns!$F6:$F57,Returns!L6:L57) -> -0.050059011 | AT6: =CORREL(Returns!$F6:$F57,Returns!M6:M57) -> 0.341613 | AU6: =CORREL(Returns!$G6:$G57,Returns!H6:H57) -> 0.74614084 | AV6: =CORREL(Returns!$G6:$G57,Returns!I6:I57) -> 0.29229335 | AW6: =CORREL(Returns!$G6:$G57,Returns!J6:J57) -> 0.23144936 | AX6: =CORREL(Returns!$G6:$G57,Returns!K6:K57) -> 0.17816828 | AY6: =CORREL(Returns!$G6:$G57,Returns!L6:L57) -> 0.18188325 | AZ6: =CORREL(Returns!$G6:$G57,Returns!M6:M57) -> 0.017690765 | BA6: =CORREL(Returns!$H6:$H57,Returns!I6:I57) -> 0.19076554 | BB6: =CORREL(Returns!$H6:$H57,Returns!J6:J57) -> 0.14358208 | BC6: =CORREL(Returns!$H6:$H57,Returns!K6:K57) -> 0.29269876 | BD6: =CORREL(Returns!$H6:$H57,Returns!L6:L57) -> 0.15563223 | BE6: =CORREL(Returns!$H6:$H57,Returns!M6:M57) -> 0.31296562 | BF6: =CORREL(Returns!$I6:$I57,Returns!J6:J57) -> -0.11078239 | BG6: =CORREL(Returns!$I6:$I57,Returns!K6:K57) -> -0.080143781 | BH6: =CORREL(Returns!$I6:$I57,Returns!L6:L57) -> -0.093632062 | BI6: =CORREL(Returns!$I6:$I57,Returns!M6:M57) -> -0.37067218 | BJ6: =CORREL(Returns!$J6:$J57,Returns!K6:K57) -> 0.28086378 | BK6: =CORREL(Returns!$J6:$J57,Returns!L6:L57) -> 0.08481926 | BL6: =CORREL(Returns!$J6:$J57,Returns!M6:M57) -> 0.13062263 | BM6: =CORREL(Returns!$K6:$K57,Returns!L6:L57) -> 0.09672332 | BN6: =CORREL(Returns!$K6:$K57,Returns!M6:M57) -> 0.38799992 | BO6: =CORREL(Returns!$L6:$L57,Returns!M6:M57) -> 0.32001511
A7: 42040 | B7: =CORREL(Returns!B7:B58,Returns!C7:C58) -> 0.32931193 | C7: =CORREL(Returns!$B7:$B58,Returns!D7:D58) -> -0.14174037 | D7: =CORREL(Returns!$B7:$B58,Returns!E7:E58) -> -0.081797484 | E7: =CORREL(Returns!$B7:$B58,Returns!F7:F58) -> -0.11377604 | F7: =CORREL(Returns!$B7:$B58,Returns!G7:G58) -> 0.39723554 | G7: =CORREL(Returns!$B7:$B58,Returns!H7:H58) -> 0.17199091 | H7: =CORREL(Returns!$B7:$B58,Returns!I7:I58) -> -0.084307528 | I7: =CORREL(Returns!$B7:$B58,Returns!J7:J58) -> 0.14094261 | J7: =CORREL(Returns!$B7:$B58,Returns!K7:K58) -> 0.18807405 | ... L7: =CORREL(Returns!$B7:$B58,Returns!M7:M58) -> -0.10436904 | M7: =CORREL(Returns!$C7:$C58,Returns!D7:D58) -> -0.11083919 | N7: =CORREL(Returns!$C7:$C58,Returns!E7:E58) -> -0.027859318 | O7: =CORREL(Returns!$C7:$C58,Returns!F7:F58) -> 0.23325644 | P7: =CORREL(Returns!$C7:$C58,Returns!G7:G58) -> 0.16995561 | Q7: =CORREL(Returns!$C7:$C58,Returns!H7:H58) -> 0.17608908 | R7: =CORREL(Returns!$C7:$C58,Returns!I7:I58) -> -0.14717699 | S7: =CORREL(Returns!$C7:$C58,Returns!J7:J58) -> -0.070391043 | T7: =CORREL(Returns!$C7:$C58,Returns!K7:K58) -> 0.10888563 | ... V7: =CORREL(Returns!$C7:$C58,Returns!M7:M58) -> 0.37025306 | W7: =CORREL(Returns!$D7:$D58,Returns!E7:E58) -> -0.1728999 | X7: =CORREL(Returns!$D7:$D58,Returns!F7:F58) -> -0.076063279 | Y7: =CORREL(Returns!$D7:$D58,Returns!G7:G58) -> 0.20783189 | Z7: =CORREL(Returns!$D7:$D58,Returns!H7:H58) -> 0.046511894 | AA7: =CORREL(Returns!$D7:$D58,Returns!I7:I58) -> 0.19450377 | AB7: =CORREL(Returns!$D7:$D58,Returns!J7:J58) -> -0.0063434705 | AC7: =CORREL(Returns!$D7:$D58,Returns!K7:K58) -> -0.14292271 | AD7: =CORREL(Returns!$D7:$D58,Returns!L7:L58) -> -0.02177801 | AE7: =CORREL(Returns!$D7:$D58,Returns!M7:M58) -> -0.22068627 | AF7: =CORREL(Returns!$E7:$E96,Returns!F7:F96) -> -0.056893156 | AG7: =CORREL(Returns!$E7:$E96,Returns!G7:G96) -> -0.0047817637 | AH7: =CORREL(Returns!$E7:$E96,Returns!H7:H96) -> 0.061987755 | AI7: =CORREL(Returns!$E7:$E96,Returns!I7:I96) -> -0.17366651 | AJ7: =CORREL(Returns!$E7:$E96,Returns!J7:J96) -> -0.0031883216 | AK7: =CORREL(Returns!$E7:$E96,Returns!K7:K96) -> 0.069443129 | AL7: =CORREL(Returns!$E7:$E96,Returns!L7:L96) -> 0.12122212 | AM7: =CORREL(Returns!$E7:$E96,Returns!M7:M96) -> 0.22305052 | AN7: =CORREL(Returns!$F7:$F58,Returns!G7:G58) -> -0.061640965 | AO7: =CORREL(Returns!$F7:$F58,Returns!H7:H58) -> 0.18079504 | AP7: =CORREL(Returns!$F7:$F58,Returns!I7:I58) -> -0.021452449 | AQ7: =CORREL(Returns!$F7:$F58,Returns!J7:J58) -> -0.13635542 | AR7: =CORREL(Returns!$F7:$F58,Returns!K7:K58) -> 0.20096543 | AS7: =CORREL(Returns!$F7:$F58,Returns!L7:L58) -> -0.049739997 | AT7: =CORREL(Returns!$F7:$F58,Returns!M7:M58) -> 0.34245338 | AU7: =CORREL(Returns!$G7:$G58,Returns!H7:H58) -> 0.74394408 | AV7: =CORREL(Returns!$G7:$G58,Returns!I7:I58) -> 0.29972822 | AW7: =CORREL(Returns!$G7:$G58,Returns!J7:J58) -> 0.22759835 | AX7: =CORREL(Returns!$G7:$G58,Returns!K7:K58) -> 0.10790269 | AY7: =CORREL(Returns!$G7:$G58,Returns!L7:L58) -> 0.1587518 | AZ7: =CORREL(Returns!$G7:$G58,Returns!M7:M58) -> 0.012377778 | BA7: =CORREL(Returns!$H7:$H58,Returns!I7:I58) -> 0.1916565 | BB7: =CORREL(Returns!$H7:$H58,Returns!J7:J58) -> 0.14533173 | BC7: =CORREL(Returns!$H7:$H58,Returns!K7:K58) -> 0.25592076 | BD7: =CORREL(Returns!$H7:$H58,Returns!L7:L58) -> 0.14826398 | BE7: =CORREL(Returns!$H7:$H58,Returns!M7:M58) -> 0.31306654 | BF7: =CORREL(Returns!$I7:$I58,Returns!J7:J58) -> -0.10567622 | BG7: =CORREL(Returns!$I7:$I58,Returns!K7:K58) -> -0.11603757 | BH7: =CORREL(Returns!$I7:$I58,Returns!L7:L58) -> -0.097031139 | BI7: =CORREL(Returns!$I7:$I58,Returns!M7:M58) -> -0.36627477 | BJ7: =CORREL(Returns!$J7:$J58,Returns!K7:K58) -> 0.2777548 | BK7: =CORREL(Returns!$J7:$J58,Returns!L7:L58) -> 0.083517518 | BL7: =CORREL(Returns!$J7:$J58,Returns!M7:M58) -> 0.12814572 | BM7: =CORREL(Returns!$K7:$K58,Returns!L7:L58) -> 0.11731527 | BN7: =CORREL(Returns!$K7:$K58,Returns!M7:M58) -> 0.39515601 | BO7: =CORREL(Returns!$L7:$L58,Returns!M7:M58) -> 0.32067195
A8: 42047 | B8: =CORREL(Returns!B8:B59,Returns!C8:C59) -> 0.33458558 | C8: =CORREL(Returns!$B8:$B59,Returns!D8:D59) -> -0.13795076 | D8: =CORREL(Returns!$B8:$B59,Returns!E8:E59) -> -0.11025794 | E8: =CORREL(Returns!$B8:$B59,Returns!F8:F59) -> -0.11322153 | F8: =CORREL(Returns!$B8:$B59,Returns!G8:G59) -> 0.39328697 | G8: =CORREL(Returns!$B8:$B59,Returns!H8:H59) -> 0.17672929 | H8: =CORREL(Returns!$B8:$B59,Returns!I8:I59) -> -0.060241402 | I8: =CORREL(Returns!$B8:$B59,Returns!J8:J59) -> 0.13976468 | J8: =CORREL(Returns!$B8:$B59,Returns!K8:K59) -> 0.16848222 | ... L8: =CORREL(Returns!$B8:$B59,Returns!M8:M59) -> -0.13949737 | M8: =CORREL(Returns!$C8:$C59,Returns!D8:D59) -> -0.10638775 | N8: =CORREL(Returns!$C8:$C59,Returns!E8:E59) -> -0.06407256 | O8: =CORREL(Returns!$C8:$C59,Returns!F8:F59) -> 0.23250805 | P8: =CORREL(Returns!$C8:$C59,Returns!G8:G59) -> 0.16757634 | Q8: =CORREL(Returns!$C8:$C59,Returns!H8:H59) -> 0.18313537 | R8: =CORREL(Returns!$C8:$C59,Returns!I8:I59) -> -0.11767537 | S8: =CORREL(Returns!$C8:$C59,Returns!J8:J59) -> -0.070061152 | T8: =CORREL(Returns!$C8:$C59,Returns!K8:K59) -> 0.081932584 | ... V8: =CORREL(Returns!$C8:$C59,Returns!M8:M59) -> 0.31617337 | W8: =CORREL(Returns!$D8:$D59,Returns!E8:E59) -> -0.17026507 | X8: =CORREL(Returns!$D8:$D59,Returns!F8:F59) -> -0.076063234 | Y8: =CORREL(Returns!$D8:$D59,Returns!G8:G59) -> 0.2043417 | Z8: =CORREL(Returns!$D8:$D59,Returns!H8:H59) -> 0.044078329 | AA8: =CORREL(Returns!$D8:$D59,Returns!I8:I59) -> 0.19405262 | AB8: =CORREL(Returns!$D8:$D59,Returns!J8:J59) -> -0.0093045598 | AC8: =CORREL(Returns!$D8:$D59,Returns!K8:K59) -> -0.14310072 | AD8: =CORREL(Returns!$D8:$D59,Returns!L8:L59) -> -0.015123396 | AE8: =CORREL(Returns!$D8:$D59,Returns!M8:M59) -> -0.21819486 | AF8: =CORREL(Returns!$E8:$E97,Returns!F8:F97) -> -0.058254347 | AG8: =CORREL(Returns!$E8:$E97,Returns!G8:G97) -> -0.00035764186 | AH8: =CORREL(Returns!$E8:$E97,Returns!H8:H97) -> 0.062084023 | AI8: =CORREL(Returns!$E8:$E97,Returns!I8:I97) -> -0.15707818 | AJ8: =CORREL(Returns!$E8:$E97,Returns!J8:J97) -> -0.0083280061 | AK8: =CORREL(Returns!$E8:$E97,Returns!K8:K97) -> 0.074543464 | AL8: =CORREL(Returns!$E8:$E97,Returns!L8:L97) -> 0.12476314 | AM8: =CORREL(Returns!$E8:$E97,Returns!M8:M97) -> 0.22452816 | AN8: =CORREL(Returns!$F8:$F59,Returns!G8:G59) -> -0.061885094 | AO8: =CORREL(Returns!$F8:$F59,Returns!H8:H59) -> 0.18181991 | AP8: =CORREL(Returns!$F8:$F59,Returns!I8:I59) -> -0.021093882 | AQ8: =CORREL(Returns!$F8:$F59,Returns!J8:J59) -> -0.13677173 | AR8: =CORREL(Returns!$F8:$F59,Returns!K8:K59) -> 0.20449401 | AS8: =CORREL(Returns!$F8:$F59,Returns!L8:L59) -> -0.049459218 | AT8: =CORREL(Returns!$F8:$F59,Returns!M8:M59) -> 0.33580844 | AU8: =CORREL(Returns!$G8:$G59,Returns!H8:H59) -> 0.73986152 | AV8: =CORREL(Returns!$G8:$G59,Returns!I8:I59) -> 0.27338689 | AW8: =CORREL(Returns!$G8:$G59,Returns!J8:J59) -> 0.2243502 | AX8: =CORREL(Returns!$G8:$G59,Returns!K8:K59) -> 0.13991111 | AY8: =CORREL(Returns!$G8:$G59,Returns!L8:L59) -> 0.16137636 | AZ8: =CORREL(Returns!$G8:$G59,Returns!M8:M59) -> 0.053123986 | BA8: =CORREL(Returns!$H8:$H59,Returns!I8:I59) -> 0.17816234 | BB8: =CORREL(Returns!$H8:$H59,Returns!J8:J59) -> 0.13772832 | BC8: =CORREL(Returns!$H8:$H59,Returns!K8:K59) -> 0.28786385 | BD8: =CORREL(Returns!$H8:$H59,Returns!L8:L59) -> 0.16416019 | BE8: =CORREL(Returns!$H8:$H59,Returns!M8:M59) -> 0.33469503 | BF8: =CORREL(Returns!$I8:$I59,Returns!J8:J59) -> -0.12130316 | BG8: =CORREL(Returns!$I8:$I59,Returns!K8:K59) -> -0.11813472 | BH8: =CORREL(Returns!$I8:$I59,Returns!L8:L59) -> -0.054209907 | BI8: =CORREL(Returns!$I8:$I59,Returns!M8:M59) -> -0.38808159 | BJ8: =CORREL(Returns!$J8:$J59,Returns!K8:K59) -> 0.30725941 | BK8: =CORREL(Returns!$J8:$J59,Returns!L8:L59) -> 0.088443845 | BL8: =CORREL(Returns!$J8:$J59,Returns!M8:M59) -> 0.15680439 | BM8: =CORREL(Returns!$K8:$K59,Returns!L8:L59) -> 0.068957277 | BN8: =CORREL(Returns!$K8:$K59,Returns!M8:M59) -> 0.38265638 | BO8: =CORREL(Returns!$L8:$L59,Returns!M8:M59) -> 0.24171793
A9: 42054 | B9: =CORREL(Returns!B9:B60,Returns!C9:C60) -> 0.35163526 | C9: =CORREL(Returns!$B9:$B60,Returns!D9:D60) -> -0.13674013 | D9: =CORREL(Returns!$B9:$B60,Returns!E9:E60) -> -0.10656746 | E9: =CORREL(Returns!$B9:$B60,Returns!F9:F60) -> -0.10783749 | F9: =CORREL(Returns!$B9:$B60,Returns!G9:G60) -> 0.37454713 | G9: =CORREL(Returns!$B9:$B60,Returns!H9:H60) -> 0.18011838 | H9: =CORREL(Returns!$B9:$B60,Returns!I9:I60) -> -0.062521397 | I9: =CORREL(Returns!$B9:$B60,Returns!J9:J60) -> 0.1283599 | J9: =CORREL(Returns!$B9:$B60,Returns!K9:K60) -> 0.18416777 | ... L9: =CORREL(Returns!$B9:$B60,Returns!M9:M60) -> -0.13662292 | M9: =CORREL(Returns!$C9:$C60,Returns!D9:D60) -> -0.097944252 | N9: =CORREL(Returns!$C9:$C60,Returns!E9:E60) -> -0.059006072 | O9: =CORREL(Returns!$C9:$C60,Returns!F9:F60) -> 0.23234997 | P9: =CORREL(Returns!$C9:$C60,Returns!G9:G60) -> 0.12801976 | Q9: =CORREL(Returns!$C9:$C60,Returns!H9:H60) -> 0.17901481 | R9: =CORREL(Returns!$C9:$C60,Returns!I9:I60) -> -0.14427062 | S9: =CORREL(Returns!$C9:$C60,Returns!J9:J60) -> -0.074062957 | T9: =CORREL(Returns!$C9:$C60,Returns!K9:K60) -> 0.10908379 | ... V9: =CORREL(Returns!$C9:$C60,Returns!M9:M60) -> 0.30040414 | W9: =CORREL(Returns!$D9:$D60,Returns!E9:E60) -> -0.16933141 | X9: =CORREL(Returns!$D9:$D60,Returns!F9:F60) -> -0.07464464 | Y9: =CORREL(Returns!$D9:$D60,Returns!G9:G60) -> 0.19926715 | Z9: =CORREL(Returns!$D9:$D60,Returns!H9:H60) -> 0.045333698 | AA9: =CORREL(Returns!$D9:$D60,Returns!I9:I60) -> 0.19494345 | AB9: =CORREL(Returns!$D9:$D60,Returns!J9:J60) -> -0.012775096 | AC9: =CORREL(Returns!$D9:$D60,Returns!K9:K60) -> -0.13704941 | AD9: =CORREL(Returns!$D9:$D60,Returns!L9:L60) -> -0.016117353 | AE9: =CORREL(Returns!$D9:$D60,Returns!M9:M60) -> -0.21753031 | AF9: =CORREL(Returns!$E9:$E98,Returns!F9:F98) -> -0.049594778 | AG9: =CORREL(Returns!$E9:$E98,Returns!G9:G98) -> 0.050156323 | AH9: =CORREL(Returns!$E9:$E98,Returns!H9:H98) -> 0.11507413 | AI9: =CORREL(Returns!$E9:$E98,Returns!I9:I98) -> -0.10257642 | AJ9: =CORREL(Returns!$E9:$E98,Returns!J9:J98) -> -0.031178282 | AK9: =CORREL(Returns!$E9:$E98,Returns!K9:K98) -> 0.026859537 | AL9: =CORREL(Returns!$E9:$E98,Returns!L9:L98) -> 0.12232482 | AM9: =CORREL(Returns!$E9:$E98,Returns!M9:M98) -> 0.22294342 | AN9: =CORREL(Returns!$F9:$F60,Returns!G9:G60) -> -0.066895954 | AO9: =CORREL(Returns!$F9:$F60,Returns!H9:H60) -> 0.18096242 | AP9: =CORREL(Returns!$F9:$F60,Returns!I9:I60) -> -0.028015483 | AQ9: =CORREL(Returns!$F9:$F60,Returns!J9:J60) -> -0.1358535 | AR9: =CORREL(Returns!$F9:$F60,Returns!K9:K60) -> 0.20567462 | AS9: =CORREL(Returns!$F9:$F60,Returns!L9:L60) -> -0.047832185 | AT9: =CORREL(Returns!$F9:$F60,Returns!M9:M60) -> 0.33354636 | AU9: =CORREL(Returns!$G9:$G60,Returns!H9:H60) -> 0.72927606 | AV9: =CORREL(Returns!$G9:$G60,Returns!I9:I60) -> 0.28255234 | AW9: =CORREL(Returns!$G9:$G60,Returns!J9:J60) -> 0.2336998 | AX9: =CORREL(Returns!$G9:$G60,Returns!K9:K60) -> 0.11206664 | AY9: =CORREL(Returns!$G9:$G60,Returns!L9:L60) -> 0.16036434 | AZ9: =CORREL(Returns!$G9:$G60,Returns!M9:M60) -> 0.053771935 | BA9: =CORREL(Returns!$H9:$H60,Returns!I9:I60) -> 0.1724913 | BB9: =CORREL(Returns!$H9:$H60,Returns!J9:J60) -> 0.14194706 | BC9: =CORREL(Returns!$H9:$H60,Returns!K9:K60) -> 0.2846766 | BD9: =CORREL(Returns!$H9:$H60,Returns!L9:L60) -> 0.16663543 | BE9: =CORREL(Returns!$H9:$H60,Returns!M9:M60) -> 0.3322278 | BF9: =CORREL(Returns!$I9:$I60,Returns!J9:J60) -> -0.10487028 | BG9: =CORREL(Returns!$I9:$I60,Returns!K9:K60) -> -0.13784692 | BH9: =CORREL(Returns!$I9:$I60,Returns!L9:L60) -> -0.049126263 | BI9: =CORREL(Returns!$I9:$I60,Returns!M9:M60) -> -0.39779129 | BJ9: =CORREL(Returns!$J9:$J60,Returns!K9:K60) -> 0.30107251 | BK9: =CORREL(Returns!$J9:$J60,Returns!L9:L60) -> 0.083813474 | BL9: =CORREL(Returns!$J9:$J60,Returns!M9:M60) -> 0.16719209 | BM9: =CORREL(Returns!$K9:$K60,Returns!L9:L60) -> 0.071303269 | BN9: =CORREL(Returns!$K9:$K60,Returns!M9:M60) -> 0.37238792 | BO9: =CORREL(Returns!$L9:$L60,Returns!M9:M60) -> 0.24665412
A10: 42061 | B10: =CORREL(Returns!B10:B61,Returns!C10:C61) -> 0.34862461 | C10: =CORREL(Returns!$B10:$B61,Returns!D10:D61) -> -0.1368068 | D10: =CORREL(Returns!$B10:$B61,Returns!E10:E61) -> -0.10306688 | E10: =CORREL(Returns!$B10:$B61,Returns!F10:F61) -> -0.1120245 | F10: =CORREL(Returns!$B10:$B61,Returns!G10:G61) -> 0.3728423 | G10: =CORREL(Returns!$B10:$B61,Returns!H10:H61) -> 0.18052168 | H10: =CORREL(Returns!$B10:$B61,Returns!I10:I61) -> -0.061306763 | I10: =CORREL(Returns!$B10:$B61,Returns!J10:J61) -> 0.13320145 | J10: =CORREL(Returns!$B10:$B61,Returns!K10:K61) -> 0.16648715 | ... L10: =CORREL(Returns!$B10:$B61,Returns!M10:M61) -> -0.1614071 | M10: =CORREL(Returns!$C10:$C61,Returns!D10:D61) -> -0.098617327 | N10: =CORREL(Returns!$C10:$C61,Returns!E10:E61) -> -0.060480382 | O10: =CORREL(Returns!$C10:$C61,Returns!F10:F61) -> 0.23165787 | P10: =CORREL(Returns!$C10:$C61,Returns!G10:G61) -> 0.12760223 | Q10: =CORREL(Returns!$C10:$C61,Returns!H10:H61) -> 0.1772223 | R10: =CORREL(Returns!$C10:$C61,Returns!I10:I61) -> -0.14947019 | S10: =CORREL(Returns!$C10:$C61,Returns!J10:J61) -> -0.07319135 | T10: =CORREL(Returns!$C10:$C61,Returns!K10:K61) -> 0.10268431 | ... V10: =CORREL(Returns!$C10:$C61,Returns!M10:M61) -> 0.28348474 | W10: =CORREL(Returns!$D10:$D61,Returns!E10:E61) -> -0.16836644 | X10: =CORREL(Returns!$D10:$D61,Returns!F10:F61) -> -0.075293629 | Y10: =CORREL(Returns!$D10:$D61,Returns!G10:G61) -> 0.19897872 | Z10: =CORREL(Returns!$D10:$D61,Returns!H10:H61) -> 0.045387569 | AA10: =CORREL(Returns!$D10:$D61,Returns!I10:I61) -> 0.1946796 | AB10: =CORREL(Returns!$D10:$D61,Returns!J10:J61) -> -0.011944625 | AC10: =CORREL(Returns!$D10:$D61,Returns!K10:K61) -> -0.14129948 | AD10: =CORREL(Returns!$D10:$D61,Returns!L10:L61) -> -0.022360337 | AE10: =CORREL(Returns!$D10:$D61,Returns!M10:M61) -> -0.21376398 | AF10: =CORREL(Returns!$E10:$E99,Returns!F10:F99) -> -0.049468097 | AG10: =CORREL(Returns!$E10:$E99,Returns!G10:G99) -> 0.062247634 | AH10: =CORREL(Returns!$E10:$E99,Returns!H10:H99) -> 0.12002199 | AI10: =CORREL(Returns!$E10:$E99,Returns!I10:I99) -> -0.096933648 | AJ10: =CORREL(Returns!$E10:$E99,Returns!J10:J99) -> -0.037234656 | AK10: =CORREL(Returns!$E10:$E99,Returns!K10:K99) -> 0.018787881 | AL10: =CORREL(Returns!$E10:$E99,Returns!L10:L99) -> 0.11920631 | AM10: =CORREL(Returns!$E10:$E99,Returns!M10:M99) -> 0.21673875 | AN10: =CORREL(Returns!$F10:$F61,Returns!G10:G61) -> -0.06656456 | AO10: =CORREL(Returns!$F10:$F61,Returns!H10:H61) -> 0.17806115 | AP10: =CORREL(Returns!$F10:$F61,Returns!I10:I61) -> -0.035426691 | AQ10: =CORREL(Returns!$F10:$F61,Returns!J10:J61) -> -0.13730609 | AR10: =CORREL(Returns!$F10:$F61,Returns!K10:K61) -> 0.2085494 | AS10: =CORREL(Returns!$F10:$F61,Returns!L10:L61) -> -0.037225253 | AT10: =CORREL(Returns!$F10:$F61,Returns!M10:M61) -> 0.33047133 | AU10: =CORREL(Returns!$G10:$G61,Returns!H10:H61) -> 0.72796785 | AV10: =CORREL(Returns!$G10:$G61,Returns!I10:I61) -> 0.27894194 | AW10: =CORREL(Returns!$G10:$G61,Returns!J10:J61) -> 0.23312178 | AX10: =CORREL(Returns!$G10:$G61,Returns!K10:K61) -> 0.11219394 | AY10: =CORREL(Returns!$G10:$G61,Returns!L10:L61) -> 0.15730989 | AZ10: =CORREL(Returns!$G10:$G61,Returns!M10:M61) -> 0.053831517 | BA10: =CORREL(Returns!$H10:$H61,Returns!I10:I61) -> 0.17373279 | BB10: =CORREL(Returns!$H10:$H61,Returns!J10:J61) -> 0.14492983 | BC10: =CORREL(Returns!$H10:$H61,Returns!K10:K61) -> 0.27527732 | BD10: =CORREL(Returns!$H10:$H61,Returns!L10:L61) -> 0.13717547 | BE10: =CORREL(Returns!$H10:$H61,Returns!M10:M61) -> 0.29933072 | BF10: =CORREL(Returns!$I10:$I61,Returns!J10:J61) -> -0.095787048 | BG10: =CORREL(Returns!$I10:$I61,Returns!K10:K61) -> -0.17063742 | BH10: =CORREL(Returns!$I10:$I61,Returns!L10:L61) -> -0.11732321 | BI10: =CORREL(Returns!$I10:$I61,Returns!M10:M61) -> -0.4344671 | BJ10: =CORREL(Returns!$J10:$J61,Returns!K10:K61) -> 0.30135996 | BK10: =CORREL(Returns!$J10:$J61,Returns!L10:L61) -> 0.070383229 | BL10: =CORREL(Returns!$J10:$J61,Returns!M10:M61) -> 0.14771833 | BM10: =CORREL(Returns!$K10:$K61,Returns!L10:L61) -> 0.065242333 | BN10: =CORREL(Returns!$K10:$K61,Returns!M10:M61) -> 0.37237907 | BO10: =CORREL(Returns!$L10:$L61,Returns!M10:M61) -> 0.30198217
A11: 42068 | B11: =CORREL(Returns!B11:B62,Returns!C11:C62) -> 0.31470935 | C11: =CORREL(Returns!$B11:$B62,Returns!D11:D62) -> -0.1555333 | D11: =CORREL(Returns!$B11:$B62,Returns!E11:E62) -> -0.043934961 | E11: =CORREL(Returns!$B11:$B62,Returns!F11:F62) -> -0.11958413 | F11: =CORREL(Returns!$B11:$B62,Returns!G11:G62) -> 0.30576415 | G11: =CORREL(Returns!$B11:$B62,Returns!H11:H62) -> 0.12871902 | H11: =CORREL(Returns!$B11:$B62,Returns!I11:I62) -> -0.070179005 | I11: =CORREL(Returns!$B11:$B62,Returns!J11:J62) -> 0.13052651 | J11: =CORREL(Returns!$B11:$B62,Returns!K11:K62) -> 0.073931993 | ... L11: =CORREL(Returns!$B11:$B62,Returns!M11:M62) -> -0.21446207 | M11: =CORREL(Returns!$C11:$C62,Returns!D11:D62) -> -0.10643729 | N11: =CORREL(Returns!$C11:$C62,Returns!E11:E62) -> 0.020782739 | O11: =CORREL(Returns!$C11:$C62,Returns!F11:F62) -> 0.23053036 | P11: =CORREL(Returns!$C11:$C62,Returns!G11:G62) -> 0.088004175 | Q11: =CORREL(Returns!$C11:$C62,Returns!H11:H62) -> 0.16006873 | R11: =CORREL(Returns!$C11:$C62,Returns!I11:I62) -> -0.15938319 | S11: =CORREL(Returns!$C11:$C62,Returns!J11:J62) -> -0.033384037 | T11: =CORREL(Returns!$C11:$C62,Returns!K11:K62) -> 0.027366073 | ... V11: =CORREL(Returns!$C11:$C62,Returns!M11:M62) -> 0.28014929 | W11: =CORREL(Returns!$D11:$D62,Returns!E11:E62) -> -0.16630689 | X11: =CORREL(Returns!$D11:$D62,Returns!F11:F62) -> -0.075293963 | Y11: =CORREL(Returns!$D11:$D62,Returns!G11:G62) -> 0.1999601 | Z11: =CORREL(Returns!$D11:$D62,Returns!H11:H62) -> 0.040418814 | AA11: =CORREL(Returns!$D11:$D62,Returns!I11:I62) -> 0.19538529 | AB11: =CORREL(Returns!$D11:$D62,Returns!J11:J62) -> -0.017935142 | AC11: =CORREL(Returns!$D11:$D62,Returns!K11:K62) -> -0.14709392 | AD11: =CORREL(Returns!$D11:$D62,Returns!L11:L62) -> -0.032792289 | AE11: =CORREL(Returns!$D11:$D62,Returns!M11:M62) -> -0.21923474 | AF11: =CORREL(Returns!$E11:$E100,Returns!F11:F100) -> -0.049673135 | AG11: =CORREL(Returns!$E11:$E100,Returns!G11:G100) -> 0.080276021 | AH11: =CORREL(Returns!$E11:$E100,Returns!H11:H100) -> 0.13241182 | AI11: =CORREL(Returns!$E11:$E100,Returns!I11:I100) -> -0.097845938 | AJ11: =CORREL(Returns!$E11:$E100,Returns!J11:J100) -> -0.031263526 | AK11: =CORREL(Returns!$E11:$E100,Returns!K11:K100) -> 0.032339691 | AL11: =CORREL(Returns!$E11:$E100,Returns!L11:L100) -> 0.11924299 | AM11: =CORREL(Returns!$E11:$E100,Returns!M11:M100) -> 0.22752456 | AN11: =CORREL(Returns!$F11:$F62,Returns!G11:G62) -> -0.069331988 | AO11: =CORREL(Returns!$F11:$F62,Returns!H11:H62) -> 0.18072637 | AP11: =CORREL(Returns!$F11:$F62,Returns!I11:I62) -> -0.035385332 | AQ11: =CORREL(Returns!$F11:$F62,Returns!J11:J62) -> -0.13372126 | AR11: =CORREL(Returns!$F11:$F62,Returns!K11:K62) -> 0.21338377 | AS11: =CORREL(Returns!$F11:$F62,Returns!L11:L62) -> -0.031882095 | AT11: =CORREL(Returns!$F11:$F62,Returns!M11:M62) -> 0.33154318 | AU11: =CORREL(Returns!$G11:$G62,Returns!H11:H62) -> 0.71720193 | AV11: =CORREL(Returns!$G11:$G62,Returns!I11:I62) -> 0.28668126 | AW11: =CORREL(Returns!$G11:$G62,Returns!J11:J62) -> 0.22915081 | AX11: =CORREL(Returns!$G11:$G62,Returns!K11:K62) -> 0.036342979 | AY11: =CORREL(Returns!$G11:$G62,Returns!L11:L62) -> 0.13106678 | AZ11: =CORREL(Returns!$G11:$G62,Returns!M11:M62) -> 0.023424123 | BA11: =CORREL(Returns!$H11:$H62,Returns!I11:I62) -> 0.17166534 | BB11: =CORREL(Returns!$H11:$H62,Returns!J11:J62) -> 0.14933156 | BC11: =CORREL(Returns!$H11:$H62,Returns!K11:K62) -> 0.22585082 | BD11: =CORREL(Returns!$H11:$H62,Returns!L11:L62) -> 0.13750076 | BE11: =CORREL(Returns!$H11:$H62,Returns!M11:M62) -> 0.28818119 | BF11: =CORREL(Returns!$I11:$I62,Returns!J11:J62) -> -0.10480972 | BG11: =CORREL(Returns!$I11:$I62,Returns!K11:K62) -> -0.16858953 | BH11: =CORREL(Returns!$I11:$I62,Returns!L11:L62) -> -0.12639306 | BI11: =CORREL(Returns!$I11:$I62,Returns!M11:M62) -> -0.44063748 | BJ11: =CORREL(Returns!$J11:$J62,Returns!K11:K62) -> 0.25051711 | BK11: =CORREL(Returns!$J11:$J62,Returns!L11:L62) -> 0.17611106 | BL11: =CORREL(Returns!$J11:$J62,Returns!M11:M62) -> 0.15948515 | BM11: =CORREL(Returns!$K11:$K62,Returns!L11:L62) -> -0.048375318 | BN11: =CORREL(Returns!$K11:$K62,Returns!M11:M62) -> 0.33535408 | BO11: =CORREL(Returns!$L11:$L62,Returns!M11:M62) -> 0.29659824
A12: 42075 | B12: =CORREL(Returns!B12:B63,Returns!C12:C63) -> 0.2962791 | C12: =CORREL(Returns!$B12:$B63,Returns!D12:D63) -> -0.15933041 | D12: =CORREL(Returns!$B12:$B63,Returns!E12:E63) -> -0.036802092 | E12: =CORREL(Returns!$B12:$B63,Returns!F12:F63) -> -0.12080329 | F12: =CORREL(Returns!$B12:$B63,Returns!G12:G63) -> 0.28863491 | G12: =CORREL(Returns!$B12:$B63,Returns!H12:H63) -> 0.13064347 | H12: =CORREL(Returns!$B12:$B63,Returns!I12:I63) -> -0.049627267 | I12: =CORREL(Returns!$B12:$B63,Returns!J12:J63) -> 0.14081887 | J12: =CORREL(Returns!$B12:$B63,Returns!K12:K63) -> 0.10493716 | ... L12: =CORREL(Returns!$B12:$B63,Returns!M12:M63) -> -0.20352823 | M12: =CORREL(Returns!$C12:$C63,Returns!D12:D63) -> -0.1142639 | N12: =CORREL(Returns!$C12:$C63,Returns!E12:E63) -> 0.046339854 | O12: =CORREL(Returns!$C12:$C63,Returns!F12:F63) -> 0.22694423 | P12: =CORREL(Returns!$C12:$C63,Returns!G12:G63) -> 0.093367688 | Q12: =CORREL(Returns!$C12:$C63,Returns!H12:H63) -> 0.17881901 | R12: =CORREL(Returns!$C12:$C63,Returns!I12:I63) -> -0.10334132 | S12: =CORREL(Returns!$C12:$C63,Returns!J12:J63) -> -0.049705376 | T12: =CORREL(Returns!$C12:$C63,Returns!K12:K63) -> 0.069661355 | ... V12: =CORREL(Returns!$C12:$C63,Returns!M12:M63) -> 0.26993592 | W12: =CORREL(Returns!$D12:$D63,Returns!E12:E63) -> -0.16472564 | X12: =CORREL(Returns!$D12:$D63,Returns!F12:F63) -> -0.076722934 | Y12: =CORREL(Returns!$D12:$D63,Returns!G12:G63) -> 0.20027477 | Z12: =CORREL(Returns!$D12:$D63,Returns!H12:H63) -> 0.042061764 | AA12: =CORREL(Returns!$D12:$D63,Returns!I12:I63) -> 0.2066726 | AB12: =CORREL(Returns!$D12:$D63,Returns!J12:J63) -> -0.022091833 | AC12: =CORREL(Returns!$D12:$D63,Returns!K12:K63) -> -0.14722384 | AD12: =CORREL(Returns!$D12:$D63,Returns!L12:L63) -> -0.034122727 | AE12: =CORREL(Returns!$D12:$D63,Returns!M12:M63) -> -0.22039156 | AF12: =CORREL(Returns!$E12:$E101,Returns!F12:F101) -> -0.04714497 | AG12: =CORREL(Returns!$E12:$E101,Returns!G12:G101) -> 0.081841121 | AH12: =CORREL(Returns!$E12:$E101,Returns!H12:H101) -> 0.14473033 | AI12: =CORREL(Returns!$E12:$E101,Returns!I12:I101) -> -0.1098916 | AJ12: =CORREL(Returns!$E12:$E101,Returns!J12:J101) -> -0.030350814 | AK12: =CORREL(Returns!$E12:$E101,Returns!K12:K101) -> 0.021024449 | AL12: =CORREL(Returns!$E12:$E101,Returns!L12:L101) -> 0.10298314 | AM12: =CORREL(Returns!$E12:$E101,Returns!M12:M101) -> 0.24117305 | AN12: =CORREL(Returns!$F12:$F63,Returns!G12:G63) -> -0.074631783 | AO12: =CORREL(Returns!$F12:$F63,Returns!H12:H63) -> 0.18112623 | AP12: =CORREL(Returns!$F12:$F63,Returns!I12:I63) -> -0.028206558 | AQ12: =CORREL(Returns!$F12:$F63,Returns!J12:J63) -> -0.12494937 | AR12: =CORREL(Returns!$F12:$F63,Returns!K12:K63) -> 0.22668658 | AS12: =CORREL(Returns!$F12:$F63,Returns!L12:L63) -> -0.030562852 | AT12: =CORREL(Returns!$F12:$F63,Returns!M12:M63) -> 0.33188665 | AU12: =CORREL(Returns!$G12:$G63,Returns!H12:H63) -> 0.7146217 | AV12: =CORREL(Returns!$G12:$G63,Returns!I12:I63) -> 0.29873547 | AW12: =CORREL(Returns!$G12:$G63,Returns!J12:J63) -> 0.1885376 | AX12: =CORREL(Returns!$G12:$G63,Returns!K12:K63) -> 0.01239344 | AY12: =CORREL(Returns!$G12:$G63,Returns!L12:L63) -> 0.12031413 | AZ12: =CORREL(Returns!$G12:$G63,Returns!M12:M63) -> -0.0034904222 | BA12: =CORREL(Returns!$H12:$H63,Returns!I12:I63) -> 0.16665126 | BB12: =CORREL(Returns!$H12:$H63,Returns!J12:J63) -> 0.14007238 | BC12: =CORREL(Returns!$H12:$H63,Returns!K12:K63) -> 0.21257528 | BD12: =CORREL(Returns!$H12:$H63,Returns!L12:L63) -> 0.13610484 | BE12: =CORREL(Returns!$H12:$H63,Returns!M12:M63) -> 0.28033788 | BF12: =CORREL(Returns!$I12:$I63,Returns!J12:J63) -> -0.10410168 | BG12: =CORREL(Returns!$I12:$I63,Returns!K12:K63) -> -0.22411328 | BH12: =CORREL(Returns!$I12:$I63,Returns!L12:L63) -> -0.12733981 | BI12: =CORREL(Returns!$I12:$I63,Returns!M12:M63) -> -0.44389008 | BJ12: =CORREL(Returns!$J12:$J63,Returns!K12:K63) -> 0.2837166 | BK12: =CORREL(Returns!$J12:$J63,Returns!L12:L63) -> 0.18261528 | BL12: =CORREL(Returns!$J12:$J63,Returns!M12:M63) -> 0.18548967 | BM12: =CORREL(Returns!$K12:$K63,Returns!L12:L63) -> -0.037012018 | BN12: =CORREL(Returns!$K12:$K63,Returns!M12:M63) -> 0.36441677 | BO12: =CORREL(Returns!$L12:$L63,Returns!M12:M63) -> 0.30052906
A13: 42082 | B13: =CORREL(Returns!B13:B64,Returns!C13:C64) -> 0.29102317 | C13: =CORREL(Returns!$B13:$B64,Returns!D13:D64) -> -0.16090922 | D13: =CORREL(Returns!$B13:$B64,Returns!E13:E64) -> -0.096133246 | E13: =CORREL(Returns!$B13:$B64,Returns!F13:F64) -> -0.13414851 | F13: =CORREL(Returns!$B13:$B64,Returns!G13:G64) -> 0.23152212 | G13: =CORREL(Returns!$B13:$B64,Returns!H13:H64) -> 0.037614079 | H13: =CORREL(Returns!$B13:$B64,Returns!I13:I64) -> -0.035872797 | I13: =CORREL(Returns!$B13:$B64,Returns!J13:J64) -> 0.12846211 | J13: =CORREL(Returns!$B13:$B64,Returns!K13:K64) -> 0.09391967 | ... L13: =CORREL(Returns!$B13:$B64,Returns!M13:M64) -> -0.19172 | M13: =CORREL(Returns!$C13:$C64,Returns!D13:D64) -> -0.11418054 | N13: =CORREL(Returns!$C13:$C64,Returns!E13:E64) -> 0.037165153 | O13: =CORREL(Returns!$C13:$C64,Returns!F13:F64) -> 0.22432791 | P13: =CORREL(Returns!$C13:$C64,Returns!G13:G64) -> 0.072291492 | Q13: =CORREL(Returns!$C13:$C64,Returns!H13:H64) -> 0.16241623 | R13: =CORREL(Returns!$C13:$C64,Returns!I13:I64) -> -0.09885771 | S13: =CORREL(Returns!$C13:$C64,Returns!J13:J64) -> -0.052503835 | T13: =CORREL(Returns!$C13:$C64,Returns!K13:K64) -> 0.066014743 | ... V13: =CORREL(Returns!$C13:$C64,Returns!M13:M64) -> 0.27827151 | W13: =CORREL(Returns!$D13:$D64,Returns!E13:E64) -> -0.16659136 | X13: =CORREL(Returns!$D13:$D64,Returns!F13:F64) -> -0.076080216 | Y13: =CORREL(Returns!$D13:$D64,Returns!G13:G64) -> 0.21370635 | Z13: =CORREL(Returns!$D13:$D64,Returns!H13:H64) -> 0.053002858 | AA13: =CORREL(Returns!$D13:$D64,Returns!I13:I64) -> 0.20588099 | AB13: =CORREL(Returns!$D13:$D64,Returns!J13:J64) -> -0.021616709 | AC13: =CORREL(Returns!$D13:$D64,Returns!K13:K64) -> -0.14658507 | AD13: =CORREL(Returns!$D13:$D64,Returns!L13:L64) -> -0.031505586 | AE13: =CORREL(Returns!$D13:$D64,Returns!M13:M64) -> -0.22176429 | AF13: =CORREL(Returns!$E13:$E102,Returns!F13:F102) -> -0.05326292 | AG13: =CORREL(Returns!$E13:$E102,Returns!G13:G102) -> 0.042706721 | AH13: =CORREL(Returns!$E13:$E102,Returns!H13:H102) -> 0.094942713 | AI13: =CORREL(Returns!$E13:$E102,Returns!I13:I102) -> -0.094601548 | AJ13: =CORREL(Returns!$E13:$E102,Returns!J13:J102) -> -0.042198405 | AK13: =CORREL(Returns!$E13:$E102,Returns!K13:K102) -> 0.016870755 | AL13: =CORREL(Returns!$E13:$E102,Returns!L13:L102) -> 0.10867112 | AM13: =CORREL(Returns!$E13:$E102,Returns!M13:M102) -> 0.2560269 | AN13: =CORREL(Returns!$F13:$F64,Returns!G13:G64) -> -0.087550878 | AO13: =CORREL(Returns!$F13:$F64,Returns!H13:H64) -> 0.18123306 | AP13: =CORREL(Returns!$F13:$F64,Returns!I13:I64) -> -0.026204516 | AQ13: =CORREL(Returns!$F13:$F64,Returns!J13:J64) -> -0.12832788 | AR13: =CORREL(Returns!$F13:$F64,Returns!K13:K64) -> 0.22508266 | AS13: =CORREL(Returns!$F13:$F64,Returns!L13:L64) -> -0.02950367 | AT13: =CORREL(Returns!$F13:$F64,Returns!M13:M64) -> 0.33137395 | AU13: =CORREL(Returns!$G13:$G64,Returns!H13:H64) -> 0.68606404 | AV13: =CORREL(Returns!$G13:$G64,Returns!I13:I64) -> 0.32623102 | AW13: =CORREL(Returns!$G13:$G64,Returns!J13:J64) -> 0.17069951 | AX13: =CORREL(Returns!$G13:$G64,Returns!K13:K64) -> -0.0038301987 | AY13: =CORREL(Returns!$G13:$G64,Returns!L13:L64) -> 0.13409496 | AZ13: =CORREL(Returns!$G13:$G64,Returns!M13:M64) -> 0.00030549102 | BA13: =CORREL(Returns!$H13:$H64,Returns!I13:I64) -> 0.20477509 | BB13: =CORREL(Returns!$H13:$H64,Returns!J13:J64) -> 0.11848558 | BC13: =CORREL(Returns!$H13:$H64,Returns!K13:K64) -> 0.2065568 | BD13: =CORREL(Returns!$H13:$H64,Returns!L13:L64) -> 0.15088518 | BE13: =CORREL(Returns!$H13:$H64,Returns!M13:M64) -> 0.31613753 | BF13: =CORREL(Returns!$I13:$I64,Returns!J13:J64) -> -0.099553017 | BG13: =CORREL(Returns!$I13:$I64,Returns!K13:K64) -> -0.2214763 | BH13: =CORREL(Returns!$I13:$I64,Returns!L13:L64) -> -0.12780343 | BI13: =CORREL(Returns!$I13:$I64,Returns!M13:M64) -> -0.44366184 | BJ13: =CORREL(Returns!$J13:$J64,Returns!K13:K64) -> 0.28050162 | BK13: =CORREL(Returns!$J13:$J64,Returns!L13:L64) -> 0.17498334 | BL13: =CORREL(Returns!$J13:$J64,Returns!M13:M64) -> 0.19300313 | BM13: =CORREL(Returns!$K13:$K64,Returns!L13:L64) -> -0.037218977 | BN13: =CORREL(Returns!$K13:$K64,Returns!M13:M64) -> 0.36600248 | BO13: =CORREL(Returns!$L13:$L64,Returns!M13:M64) -> 0.28101581
